Workbook

Sheet Start here
A1: Methodology-risk gold standard — annotation workbook
A2: Codebook | B2: docs/codebook_v1.0.md (full decision rules; this workbook only summarises them)
A4: WHAT YOU EDIT
A5: Yellow cells (sheet "Annotation") | B5: eligible, exclusion_reason, the 11 label columns (drop-downs), their evidence columns, notes, external_note, minutes, annotated_on.
A6: Do not edit | B6: order_no, set, status (formulas), pmcid, title, journal, auto_hint. Row 2 is a fictional EXAMPLE showing the expected format.
A8: WORKFLOW
A9: Step 1 | B9: Work strictly top-down in order_no. Open the paper via the "Europe PMC" link.
A10: Step 2 | B10: Decide eligibility (codebook §3). If N, give a reason and move on; the next eligible paper takes its place automatically.
A11: Step 3 | B11: Label all 11 items from the article text only. Copy verbatim evidence (ABSENT when nothing supports a label).
A12: Step 4 | B12: Log minutes and date. "set" fills itself: first 20 eligible = pilot, 21-40 = dev, 41-200 = test.
A13: Step 5 | B13: After the 20 pilot papers: stop, send the file back for codebook revision (v1.1) before continuing.
A14: Step 6 | B14: Never look at any model prediction for a paper before its labels are final.
A16: LABEL MEANINGS
A17: SAFE / RISK / UNCLEAR / N/A | B17: SAFE = the article states the safe practice. RISK = it states (or its numbers show) the risky practice. UNCLEAR = cannot tell from the text. N/A = the item does not apply.
A18: YES / NO (and variants) | B18: Absence of a statement is always NO (reporting items) or UNCLEAR (risk items), never SAFE.
A20: PROGRESS
A21: Papers screened | B21: =COUNTIF(Annotation!I3:I544,"Y")+COUNTIF(Annotation!I3:I544,"N") -> 0
A22: Eligible | B22: =COUNTIF(Annotation!I3:I544,"Y") -> 0
A23: Excluded | B23: =COUNTIF(Annotation!I3:I544,"N") -> 0
A24: Pilot papers done (target 20) | B24: =COUNTIFS(Annotation!B3:B544,"pilot",Annotation!C3:C544,"done") -> 0
A25: Dev papers done (target 20 more) | B25: =COUNTIFS(Annotation!B3:B544,"dev",Annotation!C3:C544,"done") -> 0
A26: Test papers done (target 160) | B26: =COUNTIFS(Annotation!B3:B544,"test",Annotation!C3:C544,"done") -> 0
A27: Mean minutes per completed paper | B27: =IFERROR(AVERAGEIF(Annotation!C3:C544,"done",Annotation!AI3:AI544),"-") -> -
A29: Source of the paper list | B29: Europe PMC, 2025, CC BY / CC0, deep-learning image classification (542 papers). Seeded random order (seed 20260923). See data/processed/frame_log.json.

Sheet Annotation
A1: order_no | B1: set | C1: status | D1: pmcid | E1: open | F1: title | G1: journal | H1: auto_hint | I1: eligible | J1: exclusion_reason | K1: A1_split_unit | L1: A1_evidence | M1: A2_preproc_before_split | N1: A2_evidence | O1: A3_aug_before_split | P1: A3_evidence | Q1: A4_test_for_selection | R1: A4_evidence | S1: A5_duplicate_check | T1: A5_evidence | U1: B1_external_validation | V1: B1_evidence | W1: B2_variability_reported | X1: B2_evidence | Y1: B3_stat_test_for_claim | Z1: B3_evidence | AA1: B4_baseline_protocol | AB1: B4_evidence | AC1: C1_code_available | AD1: C1_evidence | AE1: C2_data_available | AF1: C2_evidence | AG1: notes | AH1: external_note | AI1: minutes | AJ1: annotated_on
A2: EX | B2: EXAMPLE | C2: example | D2: PMC0000000 | E2: - | F2: EXAMPLE (fictional paper, not in the corpus): ResNet-50 classification of chest radiographs | G2: - | I2: Y | K2: RISK | L2: 1,200 radiographs from 400 patients || images were randomly split into 80% training and 20% testing | M2: SAFE | N2: images were resized to 224 x 224 and scaled to [0, 1] | O2: RISK | P2: after augmentation, the dataset of 6,000 images was split | Q2: UNCLEAR | R2: ABSENT | S2: NO | T2: ABSENT | U2: NO | V2: ABSENT | W2: NO | X2: ABSENT | Y2: NO | Z2: our model outperformed all compared methods | AA2: RISK | AB2: Table 5 compares our accuracy with the values reported in previous studies | AC2: YES | AD2: code is available at https://github.com/example/repo | AE2: PUBLIC | AF2: the dataset is publicly available on Kaggle | AG2: headline result = 3-class experiment | AI2: 9 | AJ2: 2026-09-24
A3: 1 | B3: =IF(I3="Y",IF(COUNTIF(I$3:I3,"Y")<=20,"pilot",IF(COUNTIF(I$3:I3,"Y")<=40,"dev",IF(COUNTIF(I$3:I3,"Y")<=200,"test","extra"))),"") | C3: =IF(I3="Y",IF(COUNTA(K3,M3,O3,Q3,S3,U3,W3,Y3,AA3,AC3,AE3)=11,"done","in progress"),IF(I3="N","excluded","")) | D3: PMC11975892 | E3: Europe PMC | F3: Early diagnosis of sepsis-associated AKI: based on destruction-replenishment contrast-enhanced ultrasonography | G3: Frontiers in medicine
A4: 2 | B4: =IF(I4="Y",IF(COUNTIF(I$3:I4,"Y")<=20,"pilot",IF(COUNTIF(I$3:I4,"Y")<=40,"dev",IF(COUNTIF(I$3:I4,"Y")<=200,"test","extra"))),"") | C4: =IF(I4="Y",IF(COUNTA(K4,M4,O4,Q4,S4,U4,W4,Y4,AA4,AC4,AE4)=11,"done","in progress"),IF(I4="N","excluded","")) | D4: PMC12412478 | E4: Europe PMC | F4: A Dynamic Contrast‐Enhanced MRI‐Based Vision Transformer Model for Distinguishing HER2‐Zero, ‐Low, and ‐Positive Expression in Breast Cancer and Exploring Model Interpretability | G4: Advanced science (Weinheim, Baden-Wurttemberg, Germany)
A5: 3 | B5: =IF(I5="Y",IF(COUNTIF(I$3:I5,"Y")<=20,"pilot",IF(COUNTIF(I$3:I5,"Y")<=40,"dev",IF(COUNTIF(I$3:I5,"Y")<=200,"test","extra"))),"") | C5: =IF(I5="Y",IF(COUNTA(K5,M5,O5,Q5,S5,U5,W5,Y5,AA5,AC5,AE5)=11,"done","in progress"),IF(I5="N","excluded","")) | D5: PMC12330392 | E5: Europe PMC | F5: Risk assessment of thyroid nodules with a multi-instance convolutional neural network | G5: Frontiers in oncology
A6: 4 | B6: =IF(I6="Y",IF(COUNTIF(I$3:I6,"Y")<=20,"pilot",IF(COUNTIF(I$3:I6,"Y")<=40,"dev",IF(COUNTIF(I$3:I6,"Y")<=200,"test","extra"))),"") | C6: =IF(I6="Y",IF(COUNTA(K6,M6,O6,Q6,S6,U6,W6,Y6,AA6,AC6,AE6)=11,"done","in progress"),IF(I6="N","excluded","")) | D6: PMC12387691 | E6: Europe PMC | F6: Evaluating the Impact of 2D MRI Slice Orientation and Location on Alzheimer’s Disease Diagnosis Using a Lightweight Convolutional Neural Network | G6: Journal of imaging
A7: 5 | B7: =IF(I7="Y",IF(COUNTIF(I$3:I7,"Y")<=20,"pilot",IF(COUNTIF(I$3:I7,"Y")<=40,"dev",IF(COUNTIF(I$3:I7,"Y")<=200,"test","extra"))),"") | C7: =IF(I7="Y",IF(COUNTA(K7,M7,O7,Q7,S7,U7,W7,Y7,AA7,AC7,AE7)=11,"done","in progress"),IF(I7="N","excluded","")) | D7: PMC12034867 | E7: Europe PMC | F7: Pilot Study of Using Machine Learning to Detect Atherosclerotic Renal Artery Stenosis From Spectral Doppler Waveforms | G7: Kidney international reports
A8: 6 | B8: =IF(I8="Y",IF(COUNTIF(I$3:I8,"Y")<=20,"pilot",IF(COUNTIF(I$3:I8,"Y")<=40,"dev",IF(COUNTIF(I$3:I8,"Y")<=200,"test","extra"))),"") | C8: =IF(I8="Y",IF(COUNTA(K8,M8,O8,Q8,S8,U8,W8,Y8,AA8,AC8,AE8)=11,"done","in progress"),IF(I8="N","excluded","")) | D8: PMC12649958 | E8: Europe PMC | F8: A Study on the Interpretability of Diabetic Retinopathy Diagnostic Models | G8: Bioengineering (Basel, Switzerland)
A9: 7 | B9: =IF(I9="Y",IF(COUNTIF(I$3:I9,"Y")<=20,"pilot",IF(COUNTIF(I$3:I9,"Y")<=40,"dev",IF(COUNTIF(I$3:I9,"Y")<=200,"test","extra"))),"") | C9: =IF(I9="Y",IF(COUNTA(K9,M9,O9,Q9,S9,U9,W9,Y9,AA9,AC9,AE9)=11,"done","in progress"),IF(I9="N","excluded","")) | D9: PMC12747359 | E9: Europe PMC | F9: Development of an automated ultrasonographic detection method for fecal retention using a transgluteal cleft approach | G9: PloS one
A10: 8 | B10: =IF(I10="Y",IF(COUNTIF(I$3:I10,"Y")<=20,"pilot",IF(COUNTIF(I$3:I10,"Y")<=40,"dev",IF(COUNTIF(I$3:I10,"Y")<=200,"test","extra"))),"") | C10: =IF(I10="Y",IF(COUNTA(K10,M10,O10,Q10,S10,U10,W10,Y10,AA10,AC10,AE10)=11,"done","in progress"),IF(I10="N","excluded","")) | D10: PMC11729117 | E10: Europe PMC | F10: Predicting intraoperative 5-ALA-induced tumor fluorescence via MRI and deep learning in gliomas with radiographic lower-grade characteristics | G10: Journal of neuro-oncology
A11: 9 | B11: =IF(I11="Y",IF(COUNTIF(I$3:I11,"Y")<=20,"pilot",IF(COUNTIF(I$3:I11,"Y")<=40,"dev",IF(COUNTIF(I$3:I11,"Y")<=200,"test","extra"))),"") | C11: =IF(I11="Y",IF(COUNTA(K11,M11,O11,Q11,S11,U11,W11,Y11,AA11,AC11,AE11)=11,"done","in progress"),IF(I11="N","excluded","")) | D11: PMC11873101 | E11: Europe PMC | F11: Contrastive self-supervised learning for neurodegenerative disorder classification | G11: Frontiers in neuroinformatics
A12: 10 | B12: =IF(I12="Y",IF(COUNTIF(I$3:I12,"Y")<=20,"pilot",IF(COUNTIF(I$3:I12,"Y")<=40,"dev",IF(COUNTIF(I$3:I12,"Y")<=200,"test","extra"))),"") | C12: =IF(I12="Y",IF(COUNTA(K12,M12,O12,Q12,S12,U12,W12,Y12,AA12,AC12,AE12)=11,"done","in progress"),IF(I12="N","excluded","")) | D12: PMC12468973 | E12: Europe PMC | F12: GlioSurvQNet: A DuelContextAttn DQN Framework for Brain Tumor Prognosis with Metaheuristic Optimization | G12: Diagnostics (Basel, Switzerland)
A13: 11 | B13: =IF(I13="Y",IF(COUNTIF(I$3:I13,"Y")<=20,"pilot",IF(COUNTIF(I$3:I13,"Y")<=40,"dev",IF(COUNTIF(I$3:I13,"Y")<=200,"test","extra"))),"") | C13: =IF(I13="Y",IF(COUNTA(K13,M13,O13,Q13,S13,U13,W13,Y13,AA13,AC13,AE13)=11,"done","in progress"),IF(I13="N","excluded","")) | D13: PMC12729362 | E13: Europe PMC | F13: Beyond VI-RADS Uncertainty: Leveraging Spatiotemporal DCE-MRI to Predict Bladder Cancer Muscle Invasion | G13: Bioengineering (Basel, Switzerland)
A14: 12 | B14: =IF(I14="Y",IF(COUNTIF(I$3:I14,"Y")<=20,"pilot",IF(COUNTIF(I$3:I14,"Y")<=40,"dev",IF(COUNTIF(I$3:I14,"Y")<=200,"test","extra"))),"") | C14: =IF(I14="Y",IF(COUNTA(K14,M14,O14,Q14,S14,U14,W14,Y14,AA14,AC14,AE14)=11,"done","in progress"),IF(I14="N","excluded","")) | D14: PMC12673201 | E14: Europe PMC | F14: Development of a deep learning algorithm for detecting significant coronary artery stenosis in whole-heart coronary magnetic resonance angiography | G14: Journal of cardiovascular magnetic resonance : official journal of the Society for Cardiovascular Magnetic Resonance
... A38: 36 | B38: =IF(I38="Y",IF(COUNTIF(I$3:I38,"Y")<=20,"pilot",IF(COUNTIF(I$3:I38,"Y")<=40,"dev",IF(COUNTIF(I$3:I38,"Y")<=200,"test","extra"))),"") | C38: =IF(I38="Y",IF(COUNTA(K38,M38,O38,Q38,S38,U38,W38,Y38,AA38,AC38,AE38)=11,"done","in progress"),IF(I38="N","excluded","")) | D38: PMC12191917 | E38: Europe PMC | F38: Characterizing Breast Tumor Heterogeneity Through IVIM-DWI Parameters and Signal Decay Analysis | G38: Diagnostics (Basel, Switzerland)
A39: 37 | B39: =IF(I39="Y",IF(COUNTIF(I$3:I39,"Y")<=20,"pilot",IF(COUNTIF(I$3:I39,"Y")<=40,"dev",IF(COUNTIF(I$3:I39,"Y")<=200,"test","extra"))),"") | C39: =IF(I39="Y",IF(COUNTA(K39,M39,O39,Q39,S39,U39,W39,Y39,AA39,AC39,AE39)=11,"done","in progress"),IF(I39="N","excluded","")) | D39: PMC11742393 | E39: Europe PMC | F39: Comparison of 1D and 3D volume measurement techniques in NF2-associated vestibular schwannoma monitoring | G39: Scientific reports | H39: no training/test wording found
A40: 38 | B40: =IF(I40="Y",IF(COUNTIF(I$3:I40,"Y")<=20,"pilot",IF(COUNTIF(I$3:I40,"Y")<=40,"dev",IF(COUNTIF(I$3:I40,"Y")<=200,"test","extra"))),"") | C40: =IF(I40="Y",IF(COUNTA(K40,M40,O40,Q40,S40,U40,W40,Y40,AA40,AC40,AE40)=11,"done","in progress"),IF(I40="N","excluded","")) | D40: PMC12654790 | E40: Europe PMC | F40: Interfacial Gap Prediction in Laser Welding of Pure Copper Overlap Joints Using Multiple Sensors | G40: Materials (Basel, Switzerland) | H40: no training/test wording found
A41: 39 | B41: =IF(I41="Y",IF(COUNTIF(I$3:I41,"Y")<=20,"pilot",IF(COUNTIF(I$3:I41,"Y")<=40,"dev",IF(COUNTIF(I$3:I41,"Y")<=200,"test","extra"))),"") | C41: =IF(I41="Y",IF(COUNTA(K41,M41,O41,Q41,S41,U41,W41,Y41,AA41,AC41,AE41)=11,"done","in progress"),IF(I41="N","excluded","")) | D41: PMC12842669 | E41: Europe PMC | F41: Adaptive Normalization Enhances the Generalization of Deep Learning Model in Chest X-Ray Classification | G41: Journal of imaging
A42: 40 | B42: =IF(I42="Y",IF(COUNTIF(I$3:I42,"Y")<=20,"pilot",IF(COUNTIF(I$3:I42,"Y")<=40,"dev",IF(COUNTIF(I$3:I42,"Y")<=200,"test","extra"))),"") | C42: =IF(I42="Y",IF(COUNTA(K42,M42,O42,Q42,S42,U42,W42,Y42,AA42,AC42,AE42)=11,"done","in progress"),IF(I42="N","excluded","")) | D42: PMC12720023 | E42: Europe PMC | F42: Proton radiography interpretation with artificial intelligence for treatment deviation detection in proton therapy☆ | G42: Physics and imaging in radiation oncology
A43: 41 | B43: =IF(I43="Y",IF(COUNTIF(I$3:I43,"Y")<=20,"pilot",IF(COUNTIF(I$3:I43,"Y")<=40,"dev",IF(COUNTIF(I$3:I43,"Y")<=200,"test","extra"))),"") | C43: =IF(I43="Y",IF(COUNTA(K43,M43,O43,Q43,S43,U43,W43,Y43,AA43,AC43,AE43)=11,"done","in progress"),IF(I43="N","excluded","")) | D43: PMC12753960 | E43: Europe PMC | F43: Secure pulmonary diagnosis using transformer-based approach to X-ray classification with KL divergence optimization | G43: Frontiers in medicine
A44: 42 | B44: =IF(I44="Y",IF(COUNTIF(I$3:I44,"Y")<=20,"pilot",IF(COUNTIF(I$3:I44,"Y")<=40,"dev",IF(COUNTIF(I$3:I44,"Y")<=200,"test","extra"))),"") | C44: =IF(I44="Y",IF(COUNTA(K44,M44,O44,Q44,S44,U44,W44,Y44,AA44,AC44,AE44)=11,"done","in progress"),IF(I44="N","excluded","")) | D44: PMC12105205 | E44: Europe PMC | F44: Detecting microcephaly and macrocephaly from ultrasound images using artificial intelligence | G44: BMC medical imaging
A45: 43 | B45: =IF(I45="Y",IF(COUNTIF(I$3:I45,"Y")<=20,"pilot",IF(COUNTIF(I$3:I45,"Y")<=40,"dev",IF(COUNTIF(I$3:I45,"Y")<=200,"test","extra"))),"") | C45: =IF(I45="Y",IF(COUNTA(K45,M45,O45,Q45,S45,U45,W45,Y45,AA45,AC45,AE45)=11,"done","in progress"),IF(I45="N","excluded","")) | D45: PMC12448012 | E45: Europe PMC | F45: Improving risk stratification and detection of early HCC using ultrasound-based deep learning models | G45: JHEP reports : innovation in hepatology
A46: 44 | B46: =IF(I46="Y",IF(COUNTIF(I$3:I46,"Y")<=20,"pilot",IF(COUNTIF(I$3:I46,"Y")<=40,"dev",IF(COUNTIF(I$3:I46,"Y")<=200,"test","extra"))),"") | C46: =IF(I46="Y",IF(COUNTA(K46,M46,O46,Q46,S46,U46,W46,Y46,AA46,AC46,AE46)=11,"done","in progress"),IF(I46="N","excluded","")) | D46: PMC12141588 | E46: Europe PMC | F46: KARNet: A Novel Deep-Learning Approach for Dementia Stage Detection in MRI Images | G46: Cureus
A47: 45 | B47: =IF(I47="Y",IF(COUNTIF(I$3:I47,"Y")<=20,"pilot",IF(COUNTIF(I$3:I47,"Y")<=40,"dev",IF(COUNTIF(I$3:I47,"Y")<=200,"test","extra"))),"") | C47: =IF(I47="Y",IF(COUNTA(K47,M47,O47,Q47,S47,U47,W47,Y47,AA47,AC47,AE47)=11,"done","in progress"),IF(I47="N","excluded","")) | D47: PMC12212162 | E47: Europe PMC | F47: Recognition and diagnosis of Alzheimer’s Disease using T1-weighted magnetic resonance imaging via integrating CNN and Swin vision transformer | G47: Clinics (Sao Paulo, Brazil)
A48: 46 | B48: =IF(I48="Y",IF(COUNTIF(I$3:I48,"Y")<=20,"pilot",IF(COUNTIF(I$3:I48,"Y")<=40,"dev",IF(COUNTIF(I$3:I48,"Y")<=200,"test","extra"))),"") | C48: =IF(I48="Y",IF(COUNTA(K48,M48,O48,Q48,S48,U48,W48,Y48,AA48,AC48,AE48)=11,"done","in progress"),IF(I48="N","excluded","")) | D48: PMC12191009 | E48: Europe PMC | F48: Hybrid Deep Learning Architecture with Adaptive Feature Fusion for Multi-Stage Alzheimer’s Disease Classification | G48: Brain sciences
A49: 47 | B49: =IF(I49="Y",IF(COUNTIF(I$3:I49,"Y")<=20,"pilot",IF(COUNTIF(I$3:I49,"Y")<=40,"dev",IF(COUNTIF(I$3:I49,"Y")<=200,"test","extra"))),"") | C49: =IF(I49="Y",IF(COUNTA(K49,M49,O49,Q49,S49,U49,W49,Y49,AA49,AC49,AE49)=11,"done","in progress"),IF(I49="N","excluded","")) | D49: PMC11786091 | E49: Europe PMC | F49: A deep learning approach versus expert clinician panel in the classification of posterior circulation infarction | G49: NeuroImage. Clinical
A50: 48 | B50: =IF(I50="Y",IF(COUNTIF(I$3:I50,"Y")<=20,"pilot",IF(COUNTIF(I$3:I50,"Y")<=40,"dev",IF(COUNTIF(I$3:I50,"Y")<=200,"test","extra"))),"") | C50: =IF(I50="Y",IF(COUNTA(K50,M50,O50,Q50,S50,U50,W50,Y50,AA50,AC50,AE50)=11,"done","in progress"),IF(I50="N","excluded","")) | D50: PMC12389973 | E50: Europe PMC | F50: Integrating Cortical Source Reconstruction and Adversarial Learning for EEG Classification | G50: Sensors (Basel, Switzerland)
A51: 49 | B51: =IF(I51="Y",IF(COUNTIF(I$3:I51,"Y")<=20,"pilot",IF(COUNTIF(I$3:I51,"Y")<=40,"dev",IF(COUNTIF(I$3:I51,"Y")<=200,"test","extra"))),"") | C51: =IF(I51="Y",IF(COUNTA(K51,M51,O51,Q51,S51,U51,W51,Y51,AA51,AC51,AE51)=11,"done","in progress"),IF(I51="N","excluded","")) | D51: PMC12838146 | E51: Europe PMC | F51: RadioGuide-DCN: A Radiomics-Guided Decorrelated Network for Medical Image Classification | G51: Bioengineering (Basel, Switzerland)
A52: 50 | B52: =IF(I52="Y",IF(COUNTIF(I$3:I52,"Y")<=20,"pilot",IF(COUNTIF(I$3:I52,"Y")<=40,"dev",IF(COUNTIF(I$3:I52,"Y")<=200,"test","extra"))),"") | C52: =IF(I52="Y",IF(COUNTA(K52,M52,O52,Q52,S52,U52,W52,Y52,AA52,AC52,AE52)=11,"done","in progress"),IF(I52="N","excluded","")) | D52: PMC12179520 | E52: Europe PMC | F52: A pathology-attention multi-instance learning framework for multimodal classification of colorectal lesions | G52: Frontiers in pharmacology
... A82: 80 | B82: =IF(I82="Y",IF(COUNTIF(I$3:I82,"Y")<=20,"pilot",IF(COUNTIF(I$3:I82,"Y")<=40,"dev",IF(COUNTIF(I$3:I82,"Y")<=200,"test","extra"))),"") | C82: =IF(I82="Y",IF(COUNTA(K82,M82,O82,Q82,S82,U82,W82,Y82,AA82,AC82,AE82)=11,"done","in progress"),IF(I82="N","excluded","")) | D82: PMC11861772 | E82: Europe PMC | F82: Preoperative prediction of the Lauren classification in gastric cancer using automated nnU-Net and radiomics: a multicenter study | G82: Insights into imaging
A83: 81 | B83: =IF(I83="Y",IF(COUNTIF(I$3:I83,"Y")<=20,"pilot",IF(COUNTIF(I$3:I83,"Y")<=40,"dev",IF(COUNTIF(I$3:I83,"Y")<=200,"test","extra"))),"") | C83: =IF(I83="Y",IF(COUNTA(K83,M83,O83,Q83,S83,U83,W83,Y83,AA83,AC83,AE83)=11,"done","in progress"),IF(I83="N","excluded","")) | D83: PMC11937600 | E83: Europe PMC | F83: Multimodal diagnosis of Alzheimer’s disease based on resting-state electroencephalography and structural magnetic resonance imaging | G83: Frontiers in physiology | H83: no training/test wording found
A84: 82 | B84: =IF(I84="Y",IF(COUNTIF(I$3:I84,"Y")<=20,"pilot",IF(COUNTIF(I$3:I84,"Y")<=40,"dev",IF(COUNTIF(I$3:I84,"Y")<=200,"test","extra"))),"") | C84: =IF(I84="Y",IF(COUNTA(K84,M84,O84,Q84,S84,U84,W84,Y84,AA84,AC84,AE84)=11,"done","in progress"),IF(I84="N","excluded","")) | D84: PMC12468869 | E84: Europe PMC | F84: Automated Detection and Segmentation of Ascending Aorta Dilation on a Non-ECG-Gated Chest CT Using Deep Learning | G84: Diagnostics (Basel, Switzerland)
A85: 83 | B85: =IF(I85="Y",IF(COUNTIF(I$3:I85,"Y")<=20,"pilot",IF(COUNTIF(I$3:I85,"Y")<=40,"dev",IF(COUNTIF(I$3:I85,"Y")<=200,"test","extra"))),"") | C85: =IF(I85="Y",IF(COUNTA(K85,M85,O85,Q85,S85,U85,W85,Y85,AA85,AC85,AE85)=11,"done","in progress"),IF(I85="N","excluded","")) | D85: PMC12020513 | E85: Europe PMC | F85: Improving healthcare sustainability using advanced brain simulations using a multi-modal deep learning strategy with VGG19 and bidirectional LSTM | G85: Frontiers in medicine
A86: 84 | B86: =IF(I86="Y",IF(COUNTIF(I$3:I86,"Y")<=20,"pilot",IF(COUNTIF(I$3:I86,"Y")<=40,"dev",IF(COUNTIF(I$3:I86,"Y")<=200,"test","extra"))),"") | C86: =IF(I86="Y",IF(COUNTA(K86,M86,O86,Q86,S86,U86,W86,Y86,AA86,AC86,AE86)=11,"done","in progress"),IF(I86="N","excluded","")) | D86: PMC12217170 | E86: Europe PMC | F86: A deep convolutional neural network-based novel class balancing for imbalance data segmentation | G86: Scientific reports
A87: 85 | B87: =IF(I87="Y",IF(COUNTIF(I$3:I87,"Y")<=20,"pilot",IF(COUNTIF(I$3:I87,"Y")<=40,"dev",IF(COUNTIF(I$3:I87,"Y")<=200,"test","extra"))),"") | C87: =IF(I87="Y",IF(COUNTA(K87,M87,O87,Q87,S87,U87,W87,Y87,AA87,AC87,AE87)=11,"done","in progress"),IF(I87="N","excluded","")) | D87: PMC12862092 | E87: Europe PMC | F87: Convolutional automatic identification of B-lines and interstitial syndrome in lung ultrasound images using pre-trained neural networks with feature fusion | G87: Frontiers in digital health
A88: 86 | B88: =IF(I88="Y",IF(COUNTIF(I$3:I88,"Y")<=20,"pilot",IF(COUNTIF(I$3:I88,"Y")<=40,"dev",IF(COUNTIF(I$3:I88,"Y")<=200,"test","extra"))),"") | C88: =IF(I88="Y",IF(COUNTA(K88,M88,O88,Q88,S88,U88,W88,Y88,AA88,AC88,AE88)=11,"done","in progress"),IF(I88="N","excluded","")) | D88: PMC12628488 | E88: Europe PMC | F88: Diffusion Models for Neuroimaging Data Augmentation: Assessing Realism and Clinical Relevance | G88: Journal of medical systems
A89: 87 | B89: =IF(I89="Y",IF(COUNTIF(I$3:I89,"Y")<=20,"pilot",IF(COUNTIF(I$3:I89,"Y")<=40,"dev",IF(COUNTIF(I$3:I89,"Y")<=200,"test","extra"))),"") | C89: =IF(I89="Y",IF(COUNTA(K89,M89,O89,Q89,S89,U89,W89,Y89,AA89,AC89,AE89)=11,"done","in progress"),IF(I89="N","excluded","")) | D89: PMC12535900 | E89: Europe PMC | F89: Multiparametric magnetic resonance imaging-based comprehensive model on prediction of lymphovascular space invasion in cervical cancer | G89: Frontiers in oncology
A90: 88 | B90: =IF(I90="Y",IF(COUNTIF(I$3:I90,"Y")<=20,"pilot",IF(COUNTIF(I$3:I90,"Y")<=40,"dev",IF(COUNTIF(I$3:I90,"Y")<=200,"test","extra"))),"") | C90: =IF(I90="Y",IF(COUNTA(K90,M90,O90,Q90,S90,U90,W90,Y90,AA90,AC90,AE90)=11,"done","in progress"),IF(I90="N","excluded","")) | D90: PMC11483474 | E90: Europe PMC | F90: Development and Validation of a Deep Learning Algorithm for Differentiation of Choroidal Nevi from Small Melanoma in Fundus Photographs | G90: Ophthalmology science
A91: 89 | B91: =IF(I91="Y",IF(COUNTIF(I$3:I91,"Y")<=20,"pilot",IF(COUNTIF(I$3:I91,"Y")<=40,"dev",IF(COUNTIF(I$3:I91,"Y")<=200,"test","extra"))),"") | C91: =IF(I91="Y",IF(COUNTA(K91,M91,O91,Q91,S91,U91,W91,Y91,AA91,AC91,AE91)=11,"done","in progress"),IF(I91="N","excluded","")) | D91: PMC12380340 | E91: Europe PMC | F91: Enhancing the early detection of Alzheimer’s disease using an integrated CNN-LSTM framework: A robust approach for fMRI-based multi-stage classification | G91: PloS one | H91: no training/test wording found
A92: 90 | B92: =IF(I92="Y",IF(COUNTIF(I$3:I92,"Y")<=20,"pilot",IF(COUNTIF(I$3:I92,"Y")<=40,"dev",IF(COUNTIF(I$3:I92,"Y")<=200,"test","extra"))),"") | C92: =IF(I92="Y",IF(COUNTA(K92,M92,O92,Q92,S92,U92,W92,Y92,AA92,AC92,AE92)=11,"done","in progress"),IF(I92="N","excluded","")) | D92: PMC11837479 | E92: Europe PMC | F92: Predicting malignant risk of ground-glass nodules using convolutional neural networks based on dual-time-point 18F-FDG PET/CT | G92: Cancer imaging : the official publication of the International Cancer Imaging Society
...

Sheet Codebook (short)
A1: Item | B1: Question | C1: Labels
A2: A1_split_unit | B2: Train/test separated by patient (or other independent unit)? | C2: SAFE / RISK / UNCLEAR
A3: A2_preproc_before_split | B3: Data-dependent preprocessing fitted on full data before split? | C3: SAFE / RISK / UNCLEAR
A4: A3_aug_before_split | B4: Augmentation / synthetic data applied before split? | C4: SAFE / RISK / UNCLEAR / N/A
A5: A4_test_for_selection | B5: Reported test set also used for tuning / early stopping / checkpoint choice? | C5: SAFE / RISK / UNCLEAR
A6: A5_duplicate_check | B6: Duplicate / near-duplicate check reported? | C6: YES / NO
A7: B1_external_validation | B7: Tested on data from a source not used in development? | C7: YES / NO
A8: B2_variability_reported | B8: Spread across folds/seeds or confidence interval reported? | C8: YES / NO
A9: B3_stat_test_for_claim | B9: Superiority claim backed by a statistical test / non-overlapping CIs? | C9: YES / NO / N/A
A10: B4_baseline_protocol | B10: Comparators evaluated under the same data and protocol? | C10: SAFE / RISK / UNCLEAR / N/A
A11: C1_code_available | B11: Study code publicly available? | C11: YES / REQUEST / NO
A12: C2_data_available | B12: Data publicly available? | C12: PUBLIC / RESTRICTED / NO
A14: Full decision rules and edge cases: docs/codebook_v1.0.md
